[2022-10-17 11:03:18,742] {taskinstance.py:1159} INFO - Dependencies all met for <TaskInstance: dbt_dag_bash.dbt_run scheduled__2022-10-15T00:00:00+00:00 [queued]>
[2022-10-17 11:03:18,747] {taskinstance.py:1159} INFO - Dependencies all met for <TaskInstance: dbt_dag_bash.dbt_run scheduled__2022-10-15T00:00:00+00:00 [queued]>
[2022-10-17 11:03:18,747] {taskinstance.py:1356} INFO - 
--------------------------------------------------------------------------------
[2022-10-17 11:03:18,747] {taskinstance.py:1357} INFO - Starting attempt 1 of 1
[2022-10-17 11:03:18,748] {taskinstance.py:1358} INFO - 
--------------------------------------------------------------------------------
[2022-10-17 11:03:18,759] {taskinstance.py:1377} INFO - Executing <Task(BashOperator): dbt_run> on 2022-10-15 00:00:00+00:00
[2022-10-17 11:03:18,762] {standard_task_runner.py:52} INFO - Started process 262885 to run task
[2022-10-17 11:03:18,766] {standard_task_runner.py:79} INFO - Running: ['airflow', 'tasks', 'run', 'dbt_dag_bash', 'dbt_run', 'scheduled__2022-10-15T00:00:00+00:00', '--job-id', '117', '--raw', '--subdir', 'DAGS_FOLDER/dbt_bashOperator.py', '--cfg-path', '/tmp/tmplct2sq72', '--error-file', '/tmp/tmp7fce5p3z']
[2022-10-17 11:03:18,766] {standard_task_runner.py:80} INFO - Job 117: Subtask dbt_run
[2022-10-17 11:03:18,807] {task_command.py:370} INFO - Running <TaskInstance: dbt_dag_bash.dbt_run scheduled__2022-10-15T00:00:00+00:00 [running]> on host ubuntu
[2022-10-17 11:03:18,869] {taskinstance.py:1569} INFO - Exporting the following env vars:
AIRFLOW_CTX_DAG_OWNER=airflow
AIRFLOW_CTX_DAG_ID=dbt_dag_bash
AIRFLOW_CTX_TASK_ID=dbt_run
AIRFLOW_CTX_EXECUTION_DATE=2022-10-15T00:00:00+00:00
AIRFLOW_CTX_TRY_NUMBER=1
AIRFLOW_CTX_DAG_RUN_ID=scheduled__2022-10-15T00:00:00+00:00
[2022-10-17 11:03:18,870] {subprocess.py:62} INFO - Tmp dir root location: 
 /tmp
[2022-10-17 11:03:18,871] {subprocess.py:74} INFO - Running command: ['bash', '-c', 'cd /home/ubuntu/airflow/dbt_project/ && dbt run -m Core']
[2022-10-17 11:03:18,879] {subprocess.py:85} INFO - Output:
[2022-10-17 11:03:22,177] {subprocess.py:92} INFO - 18:03:22  Running with dbt=1.1.0
[2022-10-17 11:03:22,266] {subprocess.py:92} INFO - 18:03:22  Found 6 models, 5 tests, 6 snapshots, 0 analyses, 400 macros, 0 operations, 7 seed files, 2 sources, 0 exposures, 0 metrics
[2022-10-17 11:03:22,272] {subprocess.py:92} INFO - 18:03:22
[2022-10-17 11:03:25,593] {subprocess.py:92} INFO - 18:03:25  Concurrency: 2 threads (target='dev')
[2022-10-17 11:03:25,593] {subprocess.py:92} INFO - 18:03:25
[2022-10-17 11:03:25,600] {subprocess.py:92} INFO - 18:03:25  1 of 2 START incremental model DBT_HAMS71.Core_City ............................ [RUN]
[2022-10-17 11:03:25,601] {subprocess.py:92} INFO - 18:03:25  2 of 2 START incremental model DBT_HAMS71.Core_Transactions .................... [RUN]
[2022-10-17 11:03:30,902] {subprocess.py:92} INFO - 18:03:30  2 of 2 OK created incremental model DBT_HAMS71.Core_Transactions ............... [[32mSUCCESS 1[0m in 5.30s]
[2022-10-17 11:03:32,293] {subprocess.py:92} INFO - 18:03:32  1 of 2 ERROR creating incremental model DBT_HAMS71.Core_City ................... [[31mERROR[0m in 6.69s]
[2022-10-17 11:03:32,296] {subprocess.py:92} INFO - 18:03:32
[2022-10-17 11:03:32,296] {subprocess.py:92} INFO - 18:03:32  Finished running 2 incremental models in 10.02s.
[2022-10-17 11:03:32,354] {subprocess.py:92} INFO - 18:03:32
[2022-10-17 11:03:32,355] {subprocess.py:92} INFO - 18:03:32  [31mCompleted with 1 error and 0 warnings:[0m
[2022-10-17 11:03:32,355] {subprocess.py:92} INFO - 18:03:32
[2022-10-17 11:03:32,355] {subprocess.py:92} INFO - 18:03:32  [33mDatabase Error in model Core_City (models/Core/Core_City.sql)[0m
[2022-10-17 11:03:32,356] {subprocess.py:92} INFO - 18:03:32    100090 (42P18): Duplicate row detected during DML action
[2022-10-17 11:03:32,356] {subprocess.py:92} INFO - 18:03:32    Row Values: ["c16a5320fa475530d9583c34fd356ef5", "101", "31", "Mushie"]
[2022-10-17 11:03:32,356] {subprocess.py:92} INFO - 18:03:32    compiled SQL at target/run/dbt_project/models/Core/Core_City.sql
[2022-10-17 11:03:32,357] {subprocess.py:92} INFO - 18:03:32
[2022-10-17 11:03:32,357] {subprocess.py:92} INFO - 18:03:32  Done. PASS=1 WARN=0 ERROR=1 SKIP=0 TOTAL=2
[2022-10-17 11:03:33,743] {subprocess.py:96} INFO - Command exited with return code 1
[2022-10-17 11:03:33,752] {taskinstance.py:1889} ERROR - Task failed with exception
Traceback (most recent call last):
  File "/home/ubuntu/airflow/airflow_env/lib/python3.8/site-packages/airflow/operators/bash.py", line 194, in execute
    raise AirflowException(
airflow.exceptions.AirflowException: Bash command failed. The command returned a non-zero exit code 1.
[2022-10-17 11:03:33,755] {taskinstance.py:1395} INFO - Marking task as FAILED. dag_id=dbt_dag_bash, task_id=dbt_run, execution_date=20221015T000000, start_date=20221017T180318, end_date=20221017T180333
[2022-10-17 11:03:33,765] {standard_task_runner.py:92} ERROR - Failed to execute job 117 for task dbt_run (Bash command failed. The command returned a non-zero exit code 1.; 262885)
[2022-10-17 11:03:33,775] {local_task_job.py:156} INFO - Task exited with return code 1
[2022-10-17 11:03:33,793] {local_task_job.py:273} INFO - 0 downstream tasks scheduled from follow-on schedule check
