[2022-10-17 10:58:13,009] {taskinstance.py:1159} INFO - Dependencies all met for <TaskInstance: dbt_dag_bash.dbt_run scheduled__2022-10-13T00:00:00+00:00 [queued]>
[2022-10-17 10:58:13,015] {taskinstance.py:1159} INFO - Dependencies all met for <TaskInstance: dbt_dag_bash.dbt_run scheduled__2022-10-13T00:00:00+00:00 [queued]>
[2022-10-17 10:58:13,015] {taskinstance.py:1356} INFO - 
--------------------------------------------------------------------------------
[2022-10-17 10:58:13,015] {taskinstance.py:1357} INFO - Starting attempt 1 of 1
[2022-10-17 10:58:13,016] {taskinstance.py:1358} INFO - 
--------------------------------------------------------------------------------
[2022-10-17 10:58:13,027] {taskinstance.py:1377} INFO - Executing <Task(BashOperator): dbt_run> on 2022-10-13 00:00:00+00:00
[2022-10-17 10:58:13,030] {standard_task_runner.py:52} INFO - Started process 257527 to run task
[2022-10-17 10:58:13,035] {standard_task_runner.py:79} INFO - Running: ['airflow', 'tasks', 'run', 'dbt_dag_bash', 'dbt_run', 'scheduled__2022-10-13T00:00:00+00:00', '--job-id', '105', '--raw', '--subdir', 'DAGS_FOLDER/dbt_bashOperator.py', '--cfg-path', '/tmp/tmpzfkqymfa', '--error-file', '/tmp/tmpohbgcpti']
[2022-10-17 10:58:13,035] {standard_task_runner.py:80} INFO - Job 105: Subtask dbt_run
[2022-10-17 10:58:13,090] {task_command.py:370} INFO - Running <TaskInstance: dbt_dag_bash.dbt_run scheduled__2022-10-13T00:00:00+00:00 [running]> on host ubuntu
[2022-10-17 10:58:13,152] {taskinstance.py:1569} INFO - Exporting the following env vars:
AIRFLOW_CTX_DAG_OWNER=airflow
AIRFLOW_CTX_DAG_ID=dbt_dag_bash
AIRFLOW_CTX_TASK_ID=dbt_run
AIRFLOW_CTX_EXECUTION_DATE=2022-10-13T00:00:00+00:00
AIRFLOW_CTX_TRY_NUMBER=1
AIRFLOW_CTX_DAG_RUN_ID=scheduled__2022-10-13T00:00:00+00:00
[2022-10-17 10:58:13,153] {subprocess.py:62} INFO - Tmp dir root location: 
 /tmp
[2022-10-17 10:58:13,153] {subprocess.py:74} INFO - Running command: ['bash', '-c', 'cd /home/ubuntu/airflow/dbt_project/ && dbt run -m Core']
[2022-10-17 10:58:13,163] {subprocess.py:85} INFO - Output:
[2022-10-17 10:58:16,309] {subprocess.py:92} INFO - 17:58:16  Running with dbt=1.1.0
[2022-10-17 10:58:16,397] {subprocess.py:92} INFO - 17:58:16  Found 6 models, 5 tests, 6 snapshots, 0 analyses, 400 macros, 0 operations, 7 seed files, 2 sources, 0 exposures, 0 metrics
[2022-10-17 10:58:16,399] {subprocess.py:92} INFO - 17:58:16
[2022-10-17 10:58:19,443] {subprocess.py:92} INFO - 17:58:19  Concurrency: 2 threads (target='dev')
[2022-10-17 10:58:19,443] {subprocess.py:92} INFO - 17:58:19
[2022-10-17 10:58:19,448] {subprocess.py:92} INFO - 17:58:19  1 of 2 START incremental model DBT_HAMS71.Core_City ............................ [RUN]
[2022-10-17 10:58:19,467] {subprocess.py:92} INFO - 17:58:19  2 of 2 START incremental model DBT_HAMS71.Core_Transactions .................... [RUN]
[2022-10-17 10:58:23,511] {subprocess.py:92} INFO - 17:58:23  1 of 2 ERROR creating incremental model DBT_HAMS71.Core_City ................... [[31mERROR[0m in 4.06s]
[2022-10-17 10:58:23,852] {subprocess.py:92} INFO - 17:58:23  2 of 2 OK created incremental model DBT_HAMS71.Core_Transactions ............... [[32mSUCCESS 1[0m in 4.38s]
[2022-10-17 10:58:23,855] {subprocess.py:92} INFO - 17:58:23
[2022-10-17 10:58:23,856] {subprocess.py:92} INFO - 17:58:23  Finished running 2 incremental models in 7.46s.
[2022-10-17 10:58:23,869] {subprocess.py:92} INFO - 17:58:23
[2022-10-17 10:58:23,870] {subprocess.py:92} INFO - 17:58:23  [31mCompleted with 1 error and 0 warnings:[0m
[2022-10-17 10:58:23,870] {subprocess.py:92} INFO - 17:58:23
[2022-10-17 10:58:23,871] {subprocess.py:92} INFO - 17:58:23  [33mDatabase Error in model Core_City (models/Core/Core_City.sql)[0m
[2022-10-17 10:58:23,871] {subprocess.py:92} INFO - 17:58:23    100090 (42P18): Duplicate row detected during DML action
[2022-10-17 10:58:23,872] {subprocess.py:92} INFO - 17:58:23    Row Values: ["c16a5320fa475530d9583c34fd356ef5", "101", "31", "Mushie"]
[2022-10-17 10:58:23,873] {subprocess.py:92} INFO - 17:58:23    compiled SQL at target/run/dbt_project/models/Core/Core_City.sql
[2022-10-17 10:58:23,873] {subprocess.py:92} INFO - 17:58:23
[2022-10-17 10:58:23,873] {subprocess.py:92} INFO - 17:58:23  Done. PASS=1 WARN=0 ERROR=1 SKIP=0 TOTAL=2
[2022-10-17 10:58:25,336] {subprocess.py:96} INFO - Command exited with return code 1
[2022-10-17 10:58:25,348] {taskinstance.py:1889} ERROR - Task failed with exception
Traceback (most recent call last):
  File "/home/ubuntu/airflow/airflow_env/lib/python3.8/site-packages/airflow/operators/bash.py", line 194, in execute
    raise AirflowException(
airflow.exceptions.AirflowException: Bash command failed. The command returned a non-zero exit code 1.
[2022-10-17 10:58:25,352] {taskinstance.py:1395} INFO - Marking task as FAILED. dag_id=dbt_dag_bash, task_id=dbt_run, execution_date=20221013T000000, start_date=20221017T175813, end_date=20221017T175825
[2022-10-17 10:58:25,367] {standard_task_runner.py:92} ERROR - Failed to execute job 105 for task dbt_run (Bash command failed. The command returned a non-zero exit code 1.; 257527)
[2022-10-17 10:58:25,377] {local_task_job.py:156} INFO - Task exited with return code 1
[2022-10-17 10:58:25,402] {local_task_job.py:273} INFO - 0 downstream tasks scheduled from follow-on schedule check
