[2022-10-10 00:49:01,445] {taskinstance.py:1159} INFO - Dependencies all met for <TaskInstance: dbt.dbt_run manual__2022-10-10T07:48:47.871073+00:00 [queued]>
[2022-10-10 00:49:01,460] {taskinstance.py:1159} INFO - Dependencies all met for <TaskInstance: dbt.dbt_run manual__2022-10-10T07:48:47.871073+00:00 [queued]>
[2022-10-10 00:49:01,460] {taskinstance.py:1356} INFO - 
--------------------------------------------------------------------------------
[2022-10-10 00:49:01,460] {taskinstance.py:1357} INFO - Starting attempt 1 of 1
[2022-10-10 00:49:01,461] {taskinstance.py:1358} INFO - 
--------------------------------------------------------------------------------
[2022-10-10 00:49:01,482] {taskinstance.py:1377} INFO - Executing <Task(DbtRunOperator): dbt_run> on 2022-10-10 07:48:47.871073+00:00
[2022-10-10 00:49:01,487] {standard_task_runner.py:52} INFO - Started process 164721 to run task
[2022-10-10 00:49:01,496] {standard_task_runner.py:79} INFO - Running: ['airflow', 'tasks', 'run', 'dbt', 'dbt_run', 'manual__2022-10-10T07:48:47.871073+00:00', '--job-id', '17', '--raw', '--subdir', 'DAGS_FOLDER/dbt_airflow.py', '--cfg-path', '/tmp/tmpv14nktbi', '--error-file', '/tmp/tmpd2ml0q6m']
[2022-10-10 00:49:01,497] {standard_task_runner.py:80} INFO - Job 17: Subtask dbt_run
[2022-10-10 00:49:01,558] {task_command.py:370} INFO - Running <TaskInstance: dbt.dbt_run manual__2022-10-10T07:48:47.871073+00:00 [running]> on host ubuntu
[2022-10-10 00:49:01,613] {taskinstance.py:1569} INFO - Exporting the following env vars:
AIRFLOW_CTX_DAG_OWNER=airflow
AIRFLOW_CTX_DAG_ID=dbt
AIRFLOW_CTX_TASK_ID=dbt_run
AIRFLOW_CTX_EXECUTION_DATE=2022-10-10T07:48:47.871073+00:00
AIRFLOW_CTX_TRY_NUMBER=1
AIRFLOW_CTX_DAG_RUN_ID=manual__2022-10-10T07:48:47.871073+00:00
[2022-10-10 00:49:01,614] {dbt_hook.py:117} INFO - dbt run
[2022-10-10 00:49:01,620] {dbt_hook.py:126} INFO - Output:
[2022-10-10 00:49:06,375] {dbt_hook.py:130} INFO - 07:49:06  Running with dbt=1.1.0
[2022-10-10 00:49:06,476] {dbt_hook.py:130} INFO - 07:49:06  Found 2 models, 4 tests, 0 snapshots, 0 analyses, 181 macros, 0 operations, 0 seed files, 0 sources, 0 exposures, 0 metrics
[2022-10-10 00:49:06,478] {dbt_hook.py:130} INFO - 07:49:06
[2022-10-10 00:49:08,564] {dbt_hook.py:130} INFO - 07:49:08  Error sending message, disabling tracking
[2022-10-10 00:49:08,565] {dbt_hook.py:130} INFO - 07:49:08  Encountered an error:
[2022-10-10 00:49:08,565] {dbt_hook.py:130} INFO - Runtime Error
[2022-10-10 00:49:08,565] {dbt_hook.py:130} INFO -   Database error while listing schemas in database "STAGING"
[2022-10-10 00:49:08,565] {dbt_hook.py:130} INFO -   Database Error
[2022-10-10 00:49:08,565] {dbt_hook.py:130} INFO -     250001: Could not connect to Snowflake backend after 0 attempt(s).Aborting
[2022-10-10 00:49:08,934] {dbt_hook.py:132} INFO - Command exited with return code 2
[2022-10-10 00:49:08,950] {taskinstance.py:1889} ERROR - Task failed with exception
Traceback (most recent call last):
  File "/home/ubuntu/airflow/airflow_env/lib/python3.8/site-packages/airflow_dbt/operators/dbt_operator.py", line 98, in execute
    self.create_hook().run_cli('run')
  File "/home/ubuntu/airflow/airflow_env/lib/python3.8/site-packages/airflow_dbt/hooks/dbt_hook.py", line 138, in run_cli
    raise AirflowException("dbt command failed")
airflow.exceptions.AirflowException: dbt command failed
[2022-10-10 00:49:08,953] {taskinstance.py:1395} INFO - Marking task as FAILED. dag_id=dbt, task_id=dbt_run, execution_date=20221010T074847, start_date=20221010T074901, end_date=20221010T074908
[2022-10-10 00:49:08,972] {standard_task_runner.py:92} ERROR - Failed to execute job 17 for task dbt_run (dbt command failed; 164721)
[2022-10-10 00:49:08,996] {local_task_job.py:156} INFO - Task exited with return code 1
[2022-10-10 00:49:09,027] {local_task_job.py:273} INFO - 0 downstream tasks scheduled from follow-on schedule check
