[2022-10-10 04:01:29,800] {taskinstance.py:1159} INFO - Dependencies all met for <TaskInstance: dbt.dbt_test manual__2022-10-10T11:00:52.821136+00:00 [queued]>
[2022-10-10 04:01:29,805] {taskinstance.py:1159} INFO - Dependencies all met for <TaskInstance: dbt.dbt_test manual__2022-10-10T11:00:52.821136+00:00 [queued]>
[2022-10-10 04:01:29,806] {taskinstance.py:1356} INFO - 
--------------------------------------------------------------------------------
[2022-10-10 04:01:29,806] {taskinstance.py:1357} INFO - Starting attempt 1 of 1
[2022-10-10 04:01:29,806] {taskinstance.py:1358} INFO - 
--------------------------------------------------------------------------------
[2022-10-10 04:01:29,816] {taskinstance.py:1377} INFO - Executing <Task(DbtTestOperator): dbt_test> on 2022-10-10 11:00:52.821136+00:00
[2022-10-10 04:01:29,820] {standard_task_runner.py:52} INFO - Started process 191780 to run task
[2022-10-10 04:01:29,826] {standard_task_runner.py:79} INFO - Running: ['airflow', 'tasks', 'run', 'dbt', 'dbt_test', 'manual__2022-10-10T11:00:52.821136+00:00', '--job-id', '42', '--raw', '--subdir', 'DAGS_FOLDER/dbt_airflow.py', '--cfg-path', '/tmp/tmpqcctyieo', '--error-file', '/tmp/tmp6j9dtrrw']
[2022-10-10 04:01:29,827] {standard_task_runner.py:80} INFO - Job 42: Subtask dbt_test
[2022-10-10 04:01:29,907] {task_command.py:370} INFO - Running <TaskInstance: dbt.dbt_test manual__2022-10-10T11:00:52.821136+00:00 [running]> on host ubuntu
[2022-10-10 04:01:30,009] {taskinstance.py:1569} INFO - Exporting the following env vars:
AIRFLOW_CTX_DAG_OWNER=airflow
AIRFLOW_CTX_DAG_ID=dbt
AIRFLOW_CTX_TASK_ID=dbt_test
AIRFLOW_CTX_EXECUTION_DATE=2022-10-10T11:00:52.821136+00:00
AIRFLOW_CTX_TRY_NUMBER=1
AIRFLOW_CTX_DAG_RUN_ID=manual__2022-10-10T11:00:52.821136+00:00
[2022-10-10 04:01:30,013] {dbt_hook.py:117} INFO - dbt test
[2022-10-10 04:01:30,032] {dbt_hook.py:126} INFO - Output:
[2022-10-10 04:01:34,075] {dbt_hook.py:130} INFO - 11:01:34  Running with dbt=1.1.0
[2022-10-10 04:01:34,238] {dbt_hook.py:130} INFO - 11:01:34  Found 6 models, 5 tests, 6 snapshots, 0 analyses, 400 macros, 0 operations, 7 seed files, 2 sources, 0 exposures, 0 metrics
[2022-10-10 04:01:34,241] {dbt_hook.py:130} INFO - 11:01:34
[2022-10-10 04:01:36,881] {dbt_hook.py:130} INFO - 11:01:36  Concurrency: 2 threads (target='dev')
[2022-10-10 04:01:36,882] {dbt_hook.py:130} INFO - 11:01:36
[2022-10-10 04:01:36,888] {dbt_hook.py:130} INFO - 11:01:36  1 of 5 START test not_null_my_first_dbt_model_id ............................... [RUN]
[2022-10-10 04:01:36,897] {dbt_hook.py:130} INFO - 11:01:36  2 of 5 START test not_null_my_second_dbt_model_id .............................. [RUN]
[2022-10-10 04:01:38,699] {dbt_hook.py:130} INFO - 11:01:38  1 of 5 ERROR not_null_my_first_dbt_model_id .................................... [[31mERROR[0m in 1.81s]
[2022-10-10 04:01:38,701] {dbt_hook.py:130} INFO - 11:01:38  3 of 5 START test unique_STG_Accounts_Account_Id ............................... [RUN]
[2022-10-10 04:01:38,900] {dbt_hook.py:130} INFO - 11:01:38  2 of 5 ERROR not_null_my_second_dbt_model_id ................................... [[31mERROR[0m in 2.00s]
[2022-10-10 04:01:38,902] {dbt_hook.py:130} INFO - 11:01:38  4 of 5 START test unique_my_first_dbt_model_id ................................. [RUN]
[2022-10-10 04:01:40,481] {dbt_hook.py:130} INFO - 11:01:40  4 of 5 ERROR unique_my_first_dbt_model_id ...................................... [[31mERROR[0m in 1.58s]
[2022-10-10 04:01:40,482] {dbt_hook.py:130} INFO - 11:01:40  5 of 5 START test unique_my_second_dbt_model_id ................................ [RUN]
[2022-10-10 04:01:40,683] {dbt_hook.py:130} INFO - 11:01:40  3 of 5 FAIL 252 unique_STG_Accounts_Account_Id ................................. [[31mFAIL 252[0m in 1.98s]
[2022-10-10 04:01:41,936] {dbt_hook.py:130} INFO - 11:01:41  5 of 5 ERROR unique_my_second_dbt_model_id ..................................... [[31mERROR[0m in 1.45s]
[2022-10-10 04:01:41,941] {dbt_hook.py:130} INFO - 11:01:41
[2022-10-10 04:01:41,941] {dbt_hook.py:130} INFO - 11:01:41  Finished running 5 tests in 7.70s.
[2022-10-10 04:01:41,966] {dbt_hook.py:130} INFO - 11:01:41
[2022-10-10 04:01:41,966] {dbt_hook.py:130} INFO - 11:01:41  [31mCompleted with 5 errors and 0 warnings:[0m
[2022-10-10 04:01:41,967] {dbt_hook.py:130} INFO - 11:01:41
[2022-10-10 04:01:41,969] {dbt_hook.py:130} INFO - 11:01:41  [33mDatabase Error in test not_null_my_first_dbt_model_id (models/example/schema.yml)[0m
[2022-10-10 04:01:41,969] {dbt_hook.py:130} INFO - 11:01:41    002003 (42S02): SQL compilation error:
[2022-10-10 04:01:41,969] {dbt_hook.py:130} INFO - 11:01:41    Object 'STAGING.DBT_HAMS71.MY_FIRST_DBT_MODEL' does not exist or not authorized.
[2022-10-10 04:01:41,970] {dbt_hook.py:130} INFO - 11:01:41    compiled SQL at target/run/dbt_project/models/example/schema.yml/not_null_my_first_dbt_model_id.sql
[2022-10-10 04:01:41,970] {dbt_hook.py:130} INFO - 11:01:41
[2022-10-10 04:01:41,970] {dbt_hook.py:130} INFO - 11:01:41  [33mDatabase Error in test not_null_my_second_dbt_model_id (models/example/schema.yml)[0m
[2022-10-10 04:01:41,970] {dbt_hook.py:130} INFO - 11:01:41    002003 (42S02): SQL compilation error:
[2022-10-10 04:01:41,971] {dbt_hook.py:130} INFO - 11:01:41    Object 'STAGING.DBT_HAMS71.MY_SECOND_DBT_MODEL' does not exist or not authorized.
[2022-10-10 04:01:41,971] {dbt_hook.py:130} INFO - 11:01:41    compiled SQL at target/run/dbt_project/models/example/schema.yml/not_null_my_second_dbt_model_id.sql
[2022-10-10 04:01:41,972] {dbt_hook.py:130} INFO - 11:01:41
[2022-10-10 04:01:41,972] {dbt_hook.py:130} INFO - 11:01:41  [33mDatabase Error in test unique_my_first_dbt_model_id (models/example/schema.yml)[0m
[2022-10-10 04:01:41,973] {dbt_hook.py:130} INFO - 11:01:41    002003 (42S02): SQL compilation error:
[2022-10-10 04:01:41,973] {dbt_hook.py:130} INFO - 11:01:41    Object 'STAGING.DBT_HAMS71.MY_FIRST_DBT_MODEL' does not exist or not authorized.
[2022-10-10 04:01:41,974] {dbt_hook.py:130} INFO - 11:01:41    compiled SQL at target/run/dbt_project/models/example/schema.yml/unique_my_first_dbt_model_id.sql
[2022-10-10 04:01:41,975] {dbt_hook.py:130} INFO - 11:01:41
[2022-10-10 04:01:41,976] {dbt_hook.py:130} INFO - 11:01:41  [31mFailure in test unique_STG_Accounts_Account_Id (seeds/properties.yml)[0m
[2022-10-10 04:01:41,977] {dbt_hook.py:130} INFO - 11:01:41    Got 252 results, configured to fail if != 0
[2022-10-10 04:01:41,978] {dbt_hook.py:130} INFO - 11:01:41
[2022-10-10 04:01:41,979] {dbt_hook.py:130} INFO - 11:01:41    compiled SQL at target/compiled/dbt_project/seeds/properties.yml/unique_STG_Accounts_Account_Id.sql
[2022-10-10 04:01:41,980] {dbt_hook.py:130} INFO - 11:01:41
[2022-10-10 04:01:41,982] {dbt_hook.py:130} INFO - 11:01:41  [33mDatabase Error in test unique_my_second_dbt_model_id (models/example/schema.yml)[0m
[2022-10-10 04:01:41,983] {dbt_hook.py:130} INFO - 11:01:41    002003 (42S02): SQL compilation error:
[2022-10-10 04:01:41,983] {dbt_hook.py:130} INFO - 11:01:41    Object 'STAGING.DBT_HAMS71.MY_SECOND_DBT_MODEL' does not exist or not authorized.
[2022-10-10 04:01:41,983] {dbt_hook.py:130} INFO - 11:01:41    compiled SQL at target/run/dbt_project/models/example/schema.yml/unique_my_second_dbt_model_id.sql
[2022-10-10 04:01:41,984] {dbt_hook.py:130} INFO - 11:01:41
[2022-10-10 04:01:41,984] {dbt_hook.py:130} INFO - 11:01:41  Done. PASS=0 WARN=0 ERROR=5 SKIP=0 TOTAL=5
[2022-10-10 04:01:43,480] {dbt_hook.py:132} INFO - Command exited with return code 1
[2022-10-10 04:01:43,493] {taskinstance.py:1889} ERROR - Task failed with exception
Traceback (most recent call last):
  File "/home/ubuntu/airflow/airflow_env/lib/python3.8/site-packages/airflow_dbt/operators/dbt_operator.py", line 107, in execute
    self.create_hook().run_cli('test')
  File "/home/ubuntu/airflow/airflow_env/lib/python3.8/site-packages/airflow_dbt/hooks/dbt_hook.py", line 138, in run_cli
    raise AirflowException("dbt command failed")
airflow.exceptions.AirflowException: dbt command failed
[2022-10-10 04:01:43,498] {taskinstance.py:1395} INFO - Marking task as FAILED. dag_id=dbt, task_id=dbt_test, execution_date=20221010T110052, start_date=20221010T110129, end_date=20221010T110143
[2022-10-10 04:01:43,521] {standard_task_runner.py:92} ERROR - Failed to execute job 42 for task dbt_test (dbt command failed; 191780)
[2022-10-10 04:01:43,560] {local_task_job.py:156} INFO - Task exited with return code 1
[2022-10-10 04:01:43,583] {local_task_job.py:273} INFO - 0 downstream tasks scheduled from follow-on schedule check
