[2022-10-10 01:37:31,367] {taskinstance.py:1159} INFO - Dependencies all met for <TaskInstance: dbt.dbt_test manual__2022-10-10T08:36:34.934093+00:00 [queued]>
[2022-10-10 01:37:31,372] {taskinstance.py:1159} INFO - Dependencies all met for <TaskInstance: dbt.dbt_test manual__2022-10-10T08:36:34.934093+00:00 [queued]>
[2022-10-10 01:37:31,372] {taskinstance.py:1356} INFO - 
--------------------------------------------------------------------------------
[2022-10-10 01:37:31,372] {taskinstance.py:1357} INFO - Starting attempt 1 of 1
[2022-10-10 01:37:31,373] {taskinstance.py:1358} INFO - 
--------------------------------------------------------------------------------
[2022-10-10 01:37:31,386] {taskinstance.py:1377} INFO - Executing <Task(DbtTestOperator): dbt_test> on 2022-10-10 08:36:34.934093+00:00
[2022-10-10 01:37:31,389] {standard_task_runner.py:52} INFO - Started process 174842 to run task
[2022-10-10 01:37:31,393] {standard_task_runner.py:79} INFO - Running: ['airflow', 'tasks', 'run', 'dbt', 'dbt_test', 'manual__2022-10-10T08:36:34.934093+00:00', '--job-id', '40', '--raw', '--subdir', 'DAGS_FOLDER/dbt_airflow.py', '--cfg-path', '/tmp/tmpe58ylnpt', '--error-file', '/tmp/tmpkcoefjvl']
[2022-10-10 01:37:31,394] {standard_task_runner.py:80} INFO - Job 40: Subtask dbt_test
[2022-10-10 01:37:31,431] {task_command.py:370} INFO - Running <TaskInstance: dbt.dbt_test manual__2022-10-10T08:36:34.934093+00:00 [running]> on host ubuntu
[2022-10-10 01:37:31,484] {taskinstance.py:1569} INFO - Exporting the following env vars:
AIRFLOW_CTX_DAG_OWNER=airflow
AIRFLOW_CTX_DAG_ID=dbt
AIRFLOW_CTX_TASK_ID=dbt_test
AIRFLOW_CTX_EXECUTION_DATE=2022-10-10T08:36:34.934093+00:00
AIRFLOW_CTX_TRY_NUMBER=1
AIRFLOW_CTX_DAG_RUN_ID=manual__2022-10-10T08:36:34.934093+00:00
[2022-10-10 01:37:31,485] {dbt_hook.py:117} INFO - dbt test
[2022-10-10 01:37:31,490] {dbt_hook.py:126} INFO - Output:
[2022-10-10 01:37:34,161] {dbt_hook.py:130} INFO - 08:37:34  Running with dbt=1.1.0
[2022-10-10 01:37:34,242] {dbt_hook.py:130} INFO - 08:37:34  Found 6 models, 5 tests, 6 snapshots, 0 analyses, 400 macros, 0 operations, 7 seed files, 2 sources, 0 exposures, 0 metrics
[2022-10-10 01:37:34,244] {dbt_hook.py:130} INFO - 08:37:34
[2022-10-10 01:37:35,797] {dbt_hook.py:130} INFO - 08:37:35  Concurrency: 2 threads (target='dev')
[2022-10-10 01:37:35,798] {dbt_hook.py:130} INFO - 08:37:35
[2022-10-10 01:37:35,805] {dbt_hook.py:130} INFO - 08:37:35  1 of 5 START test not_null_my_first_dbt_model_id ............................... [RUN]
[2022-10-10 01:37:35,806] {dbt_hook.py:130} INFO - 08:37:35  2 of 5 START test not_null_my_second_dbt_model_id .............................. [RUN]
[2022-10-10 01:37:37,352] {dbt_hook.py:130} INFO - 08:37:37  2 of 5 ERROR not_null_my_second_dbt_model_id ................................... [[31mERROR[0m in 1.55s]
[2022-10-10 01:37:37,353] {dbt_hook.py:130} INFO - 08:37:37  3 of 5 START test unique_STG_Accounts_Account_Id ............................... [RUN]
[2022-10-10 01:37:37,371] {dbt_hook.py:130} INFO - 08:37:37  1 of 5 ERROR not_null_my_first_dbt_model_id .................................... [[31mERROR[0m in 1.57s]
[2022-10-10 01:37:37,372] {dbt_hook.py:130} INFO - 08:37:37  4 of 5 START test unique_my_first_dbt_model_id ................................. [RUN]
[2022-10-10 01:37:38,982] {dbt_hook.py:130} INFO - 08:37:38  3 of 5 FAIL 252 unique_STG_Accounts_Account_Id ................................. [[31mFAIL 252[0m in 1.63s]
[2022-10-10 01:37:38,982] {dbt_hook.py:130} INFO - 08:37:38  4 of 5 ERROR unique_my_first_dbt_model_id ...................................... [[31mERROR[0m in 1.61s]
[2022-10-10 01:37:38,984] {dbt_hook.py:130} INFO - 08:37:38  5 of 5 START test unique_my_second_dbt_model_id ................................ [RUN]
[2022-10-10 01:37:40,274] {dbt_hook.py:130} INFO - 08:37:40  5 of 5 ERROR unique_my_second_dbt_model_id ..................................... [[31mERROR[0m in 1.29s]
[2022-10-10 01:37:40,277] {dbt_hook.py:130} INFO - 08:37:40
[2022-10-10 01:37:40,277] {dbt_hook.py:130} INFO - 08:37:40  Finished running 5 tests in 6.03s.
[2022-10-10 01:37:40,289] {dbt_hook.py:130} INFO - 08:37:40
[2022-10-10 01:37:40,289] {dbt_hook.py:130} INFO - 08:37:40  [31mCompleted with 5 errors and 0 warnings:[0m
[2022-10-10 01:37:40,289] {dbt_hook.py:130} INFO - 08:37:40
[2022-10-10 01:37:40,290] {dbt_hook.py:130} INFO - 08:37:40  [33mDatabase Error in test not_null_my_second_dbt_model_id (models/example/schema.yml)[0m
[2022-10-10 01:37:40,290] {dbt_hook.py:130} INFO - 08:37:40    002003 (42S02): SQL compilation error:
[2022-10-10 01:37:40,290] {dbt_hook.py:130} INFO - 08:37:40    Object 'STAGING.DBT_HAMS71.MY_SECOND_DBT_MODEL' does not exist or not authorized.
[2022-10-10 01:37:40,291] {dbt_hook.py:130} INFO - 08:37:40    compiled SQL at target/run/dbt_project/models/example/schema.yml/not_null_my_second_dbt_model_id.sql
[2022-10-10 01:37:40,291] {dbt_hook.py:130} INFO - 08:37:40
[2022-10-10 01:37:40,291] {dbt_hook.py:130} INFO - 08:37:40  [33mDatabase Error in test not_null_my_first_dbt_model_id (models/example/schema.yml)[0m
[2022-10-10 01:37:40,292] {dbt_hook.py:130} INFO - 08:37:40    002003 (42S02): SQL compilation error:
[2022-10-10 01:37:40,292] {dbt_hook.py:130} INFO - 08:37:40    Object 'STAGING.DBT_HAMS71.MY_FIRST_DBT_MODEL' does not exist or not authorized.
[2022-10-10 01:37:40,292] {dbt_hook.py:130} INFO - 08:37:40    compiled SQL at target/run/dbt_project/models/example/schema.yml/not_null_my_first_dbt_model_id.sql
[2022-10-10 01:37:40,292] {dbt_hook.py:130} INFO - 08:37:40
[2022-10-10 01:37:40,293] {dbt_hook.py:130} INFO - 08:37:40  [31mFailure in test unique_STG_Accounts_Account_Id (seeds/properties.yml)[0m
[2022-10-10 01:37:40,293] {dbt_hook.py:130} INFO - 08:37:40    Got 252 results, configured to fail if != 0
[2022-10-10 01:37:40,293] {dbt_hook.py:130} INFO - 08:37:40
[2022-10-10 01:37:40,293] {dbt_hook.py:130} INFO - 08:37:40    compiled SQL at target/compiled/dbt_project/seeds/properties.yml/unique_STG_Accounts_Account_Id.sql
[2022-10-10 01:37:40,294] {dbt_hook.py:130} INFO - 08:37:40
[2022-10-10 01:37:40,294] {dbt_hook.py:130} INFO - 08:37:40  [33mDatabase Error in test unique_my_first_dbt_model_id (models/example/schema.yml)[0m
[2022-10-10 01:37:40,295] {dbt_hook.py:130} INFO - 08:37:40    002003 (42S02): SQL compilation error:
[2022-10-10 01:37:40,295] {dbt_hook.py:130} INFO - 08:37:40    Object 'STAGING.DBT_HAMS71.MY_FIRST_DBT_MODEL' does not exist or not authorized.
[2022-10-10 01:37:40,295] {dbt_hook.py:130} INFO - 08:37:40    compiled SQL at target/run/dbt_project/models/example/schema.yml/unique_my_first_dbt_model_id.sql
[2022-10-10 01:37:40,295] {dbt_hook.py:130} INFO - 08:37:40
[2022-10-10 01:37:40,295] {dbt_hook.py:130} INFO - 08:37:40  [33mDatabase Error in test unique_my_second_dbt_model_id (models/example/schema.yml)[0m
[2022-10-10 01:37:40,296] {dbt_hook.py:130} INFO - 08:37:40    002003 (42S02): SQL compilation error:
[2022-10-10 01:37:40,296] {dbt_hook.py:130} INFO - 08:37:40    Object 'STAGING.DBT_HAMS71.MY_SECOND_DBT_MODEL' does not exist or not authorized.
[2022-10-10 01:37:40,296] {dbt_hook.py:130} INFO - 08:37:40    compiled SQL at target/run/dbt_project/models/example/schema.yml/unique_my_second_dbt_model_id.sql
[2022-10-10 01:37:40,297] {dbt_hook.py:130} INFO - 08:37:40
[2022-10-10 01:37:40,297] {dbt_hook.py:130} INFO - 08:37:40  Done. PASS=0 WARN=0 ERROR=5 SKIP=0 TOTAL=5
[2022-10-10 01:37:41,784] {dbt_hook.py:132} INFO - Command exited with return code 1
[2022-10-10 01:37:41,794] {taskinstance.py:1889} ERROR - Task failed with exception
Traceback (most recent call last):
  File "/home/ubuntu/airflow/airflow_env/lib/python3.8/site-packages/airflow_dbt/operators/dbt_operator.py", line 107, in execute
    self.create_hook().run_cli('test')
  File "/home/ubuntu/airflow/airflow_env/lib/python3.8/site-packages/airflow_dbt/hooks/dbt_hook.py", line 138, in run_cli
    raise AirflowException("dbt command failed")
airflow.exceptions.AirflowException: dbt command failed
[2022-10-10 01:37:41,798] {taskinstance.py:1395} INFO - Marking task as FAILED. dag_id=dbt, task_id=dbt_test, execution_date=20221010T083634, start_date=20221010T083731, end_date=20221010T083741
[2022-10-10 01:37:41,813] {standard_task_runner.py:92} ERROR - Failed to execute job 40 for task dbt_test (dbt command failed; 174842)
[2022-10-10 01:37:41,840] {local_task_job.py:156} INFO - Task exited with return code 1
[2022-10-10 01:37:41,853] {local_task_job.py:273} INFO - 0 downstream tasks scheduled from follow-on schedule check
