[2022-10-10 01:07:11,983] {taskinstance.py:1159} INFO - Dependencies all met for <TaskInstance: dbt.dbt_snapshot manual__2022-10-10T08:06:12.511346+00:00 [queued]>
[2022-10-10 01:07:11,994] {taskinstance.py:1159} INFO - Dependencies all met for <TaskInstance: dbt.dbt_snapshot manual__2022-10-10T08:06:12.511346+00:00 [queued]>
[2022-10-10 01:07:11,995] {taskinstance.py:1356} INFO - 
--------------------------------------------------------------------------------
[2022-10-10 01:07:11,995] {taskinstance.py:1357} INFO - Starting attempt 1 of 1
[2022-10-10 01:07:11,995] {taskinstance.py:1358} INFO - 
--------------------------------------------------------------------------------
[2022-10-10 01:07:12,018] {taskinstance.py:1377} INFO - Executing <Task(DbtSnapshotOperator): dbt_snapshot> on 2022-10-10 08:06:12.511346+00:00
[2022-10-10 01:07:12,026] {standard_task_runner.py:52} INFO - Started process 169212 to run task
[2022-10-10 01:07:12,037] {standard_task_runner.py:79} INFO - Running: ['airflow', 'tasks', 'run', 'dbt', 'dbt_snapshot', 'manual__2022-10-10T08:06:12.511346+00:00', '--job-id', '27', '--raw', '--subdir', 'DAGS_FOLDER/dbt_airflow.py', '--cfg-path', '/tmp/tmpotyziy7p', '--error-file', '/tmp/tmp_rz3y2xq']
[2022-10-10 01:07:12,039] {standard_task_runner.py:80} INFO - Job 27: Subtask dbt_snapshot
[2022-10-10 01:07:12,125] {task_command.py:370} INFO - Running <TaskInstance: dbt.dbt_snapshot manual__2022-10-10T08:06:12.511346+00:00 [running]> on host ubuntu
[2022-10-10 01:07:12,202] {taskinstance.py:1569} INFO - Exporting the following env vars:
AIRFLOW_CTX_DAG_OWNER=airflow
AIRFLOW_CTX_DAG_ID=dbt
AIRFLOW_CTX_TASK_ID=dbt_snapshot
AIRFLOW_CTX_EXECUTION_DATE=2022-10-10T08:06:12.511346+00:00
AIRFLOW_CTX_TRY_NUMBER=1
AIRFLOW_CTX_DAG_RUN_ID=manual__2022-10-10T08:06:12.511346+00:00
[2022-10-10 01:07:12,204] {dbt_hook.py:117} INFO - dbt snapshot --target DBT_HAMS71
[2022-10-10 01:07:12,213] {dbt_hook.py:126} INFO - Output:
[2022-10-10 01:07:16,033] {dbt_hook.py:130} INFO - 08:07:16  Encountered an error while reading profiles:
[2022-10-10 01:07:16,034] {dbt_hook.py:130} INFO - 08:07:16    ERROR: Runtime Error
[2022-10-10 01:07:16,034] {dbt_hook.py:130} INFO -   The profile 'dbt_project' does not have a target named 'DBT_HAMS71'. The valid target names for this profile are:
[2022-10-10 01:07:16,034] {dbt_hook.py:130} INFO -    - dev
[2022-10-10 01:07:16,035] {dbt_hook.py:130} INFO - 08:07:16  Defined profiles:
[2022-10-10 01:07:16,035] {dbt_hook.py:130} INFO - 08:07:16   - dbt_model
[2022-10-10 01:07:16,036] {dbt_hook.py:130} INFO - 08:07:16   - dbt_project
[2022-10-10 01:07:16,036] {dbt_hook.py:130} INFO - 08:07:16
[2022-10-10 01:07:16,036] {dbt_hook.py:130} INFO - For more information on configuring profiles, please consult the dbt docs:
[2022-10-10 01:07:16,036] {dbt_hook.py:130} INFO - 
[2022-10-10 01:07:16,036] {dbt_hook.py:130} INFO - https://docs.getdbt.com/docs/configure-your-profile
[2022-10-10 01:07:16,036] {dbt_hook.py:130} INFO - 
[2022-10-10 01:07:16,048] {dbt_hook.py:130} INFO - 08:07:16  Encountered an error:
[2022-10-10 01:07:16,048] {dbt_hook.py:130} INFO - Runtime Error
[2022-10-10 01:07:16,048] {dbt_hook.py:130} INFO -   Could not run dbt
[2022-10-10 01:07:16,285] {dbt_hook.py:132} INFO - Command exited with return code 2
[2022-10-10 01:07:16,298] {taskinstance.py:1889} ERROR - Task failed with exception
Traceback (most recent call last):
  File "/home/ubuntu/airflow/airflow_env/lib/python3.8/site-packages/airflow_dbt/operators/dbt_operator.py", line 126, in execute
    self.create_hook().run_cli('snapshot')
  File "/home/ubuntu/airflow/airflow_env/lib/python3.8/site-packages/airflow_dbt/hooks/dbt_hook.py", line 138, in run_cli
    raise AirflowException("dbt command failed")
airflow.exceptions.AirflowException: dbt command failed
[2022-10-10 01:07:16,303] {taskinstance.py:1395} INFO - Marking task as FAILED. dag_id=dbt, task_id=dbt_snapshot, execution_date=20221010T080612, start_date=20221010T080711, end_date=20221010T080716
[2022-10-10 01:07:16,318] {standard_task_runner.py:92} ERROR - Failed to execute job 27 for task dbt_snapshot (dbt command failed; 169212)
[2022-10-10 01:07:16,335] {local_task_job.py:156} INFO - Task exited with return code 1
[2022-10-10 01:07:16,374] {local_task_job.py:273} INFO - 0 downstream tasks scheduled from follow-on schedule check
