[2022-10-10 01:11:04,423] {taskinstance.py:1159} INFO - Dependencies all met for <TaskInstance: dbt.dbt_run manual__2022-10-10T08:10:32.922589+00:00 [queued]>
[2022-10-10 01:11:04,444] {taskinstance.py:1159} INFO - Dependencies all met for <TaskInstance: dbt.dbt_run manual__2022-10-10T08:10:32.922589+00:00 [queued]>
[2022-10-10 01:11:04,446] {taskinstance.py:1356} INFO - 
--------------------------------------------------------------------------------
[2022-10-10 01:11:04,447] {taskinstance.py:1357} INFO - Starting attempt 1 of 1
[2022-10-10 01:11:04,447] {taskinstance.py:1358} INFO - 
--------------------------------------------------------------------------------
[2022-10-10 01:11:04,470] {taskinstance.py:1377} INFO - Executing <Task(DbtRunOperator): dbt_run> on 2022-10-10 08:10:32.922589+00:00
[2022-10-10 01:11:04,476] {standard_task_runner.py:52} INFO - Started process 169987 to run task
[2022-10-10 01:11:04,489] {standard_task_runner.py:79} INFO - Running: ['airflow', 'tasks', 'run', 'dbt', 'dbt_run', 'manual__2022-10-10T08:10:32.922589+00:00', '--job-id', '29', '--raw', '--subdir', 'DAGS_FOLDER/dbt_airflow.py', '--cfg-path', '/tmp/tmpt9i6ff73', '--error-file', '/tmp/tmp4qyspi65']
[2022-10-10 01:11:04,491] {standard_task_runner.py:80} INFO - Job 29: Subtask dbt_run
[2022-10-10 01:11:04,602] {task_command.py:370} INFO - Running <TaskInstance: dbt.dbt_run manual__2022-10-10T08:10:32.922589+00:00 [running]> on host ubuntu
[2022-10-10 01:11:04,667] {taskinstance.py:1569} INFO - Exporting the following env vars:
AIRFLOW_CTX_DAG_OWNER=airflow
AIRFLOW_CTX_DAG_ID=dbt
AIRFLOW_CTX_TASK_ID=dbt_run
AIRFLOW_CTX_EXECUTION_DATE=2022-10-10T08:10:32.922589+00:00
AIRFLOW_CTX_TRY_NUMBER=1
AIRFLOW_CTX_DAG_RUN_ID=manual__2022-10-10T08:10:32.922589+00:00
[2022-10-10 01:11:04,668] {dbt_hook.py:117} INFO - dbt run --select Core
[2022-10-10 01:11:04,680] {dbt_hook.py:126} INFO - Output:
[2022-10-10 01:11:08,669] {dbt_hook.py:130} INFO - 08:11:08  Running with dbt=1.1.0
[2022-10-10 01:11:08,776] {dbt_hook.py:130} INFO - 08:11:08  Found 6 models, 5 tests, 7 snapshots, 0 analyses, 400 macros, 0 operations, 7 seed files, 2 sources, 0 exposures, 0 metrics
[2022-10-10 01:11:08,780] {dbt_hook.py:130} INFO - 08:11:08
[2022-10-10 01:11:12,557] {dbt_hook.py:130} INFO - 08:11:12  Concurrency: 2 threads (target='dev')
[2022-10-10 01:11:12,558] {dbt_hook.py:130} INFO - 08:11:12
[2022-10-10 01:11:12,565] {dbt_hook.py:130} INFO - 08:11:12  1 of 2 START incremental model DBT_HAMS71.Core_City ............................ [RUN]
[2022-10-10 01:11:12,580] {dbt_hook.py:130} INFO - 08:11:12  2 of 2 START incremental model DBT_HAMS71.Core_Transactions .................... [RUN]
[2022-10-10 01:11:16,906] {dbt_hook.py:130} INFO - 08:11:16  1 of 2 ERROR creating incremental model DBT_HAMS71.Core_City ................... [[31mERROR[0m in 4.33s]
[2022-10-10 01:11:17,582] {dbt_hook.py:130} INFO - 08:11:17  2 of 2 OK created incremental model DBT_HAMS71.Core_Transactions ............... [[32mSUCCESS 1[0m in 4.99s]
[2022-10-10 01:11:17,640] {dbt_hook.py:130} INFO - 08:11:17
[2022-10-10 01:11:17,641] {dbt_hook.py:130} INFO - 08:11:17  Finished running 2 incremental models in 8.86s.
[2022-10-10 01:11:17,724] {dbt_hook.py:130} INFO - 08:11:17
[2022-10-10 01:11:17,740] {dbt_hook.py:130} INFO - 08:11:17  [31mCompleted with 1 error and 0 warnings:[0m
[2022-10-10 01:11:17,740] {dbt_hook.py:130} INFO - 08:11:17
[2022-10-10 01:11:17,741] {dbt_hook.py:130} INFO - 08:11:17  [33mDatabase Error in model Core_City (models/Core/Core_City.sql)[0m
[2022-10-10 01:11:17,741] {dbt_hook.py:130} INFO - 08:11:17    100090 (42P18): Duplicate row detected during DML action
[2022-10-10 01:11:17,741] {dbt_hook.py:130} INFO - 08:11:17    Row Values: ["c16a5320fa475530d9583c34fd356ef5", "101", "31", "Mushie"]
[2022-10-10 01:11:17,741] {dbt_hook.py:130} INFO - 08:11:17    compiled SQL at target/run/dbt_project/models/Core/Core_City.sql
[2022-10-10 01:11:17,741] {dbt_hook.py:130} INFO - 08:11:17
[2022-10-10 01:11:17,741] {dbt_hook.py:130} INFO - 08:11:17  Done. PASS=1 WARN=0 ERROR=1 SKIP=0 TOTAL=2
[2022-10-10 01:11:19,957] {dbt_hook.py:132} INFO - Command exited with return code 1
[2022-10-10 01:11:19,983] {taskinstance.py:1889} ERROR - Task failed with exception
Traceback (most recent call last):
  File "/home/ubuntu/airflow/airflow_env/lib/python3.8/site-packages/airflow_dbt/operators/dbt_operator.py", line 98, in execute
    self.create_hook().run_cli('run')
  File "/home/ubuntu/airflow/airflow_env/lib/python3.8/site-packages/airflow_dbt/hooks/dbt_hook.py", line 138, in run_cli
    raise AirflowException("dbt command failed")
airflow.exceptions.AirflowException: dbt command failed
[2022-10-10 01:11:19,992] {taskinstance.py:1395} INFO - Marking task as FAILED. dag_id=dbt, task_id=dbt_run, execution_date=20221010T081032, start_date=20221010T081104, end_date=20221010T081119
[2022-10-10 01:11:20,031] {standard_task_runner.py:92} ERROR - Failed to execute job 29 for task dbt_run (dbt command failed; 169987)
[2022-10-10 01:11:20,043] {local_task_job.py:156} INFO - Task exited with return code 1
[2022-10-10 01:11:20,106] {local_task_job.py:273} INFO - 0 downstream tasks scheduled from follow-on schedule check
